[2025-05-10T03:34:10.920+0000] {task_context_logger.py:104} ERROR - Executor reports task instance <TaskInstance: get_price_btc_price_by_day.get_data scheduled__2025-05-08T21:00:00+00:00 [queued]> finished (failed) although the task says it's queued. (Info: None) Was the task killed externally?
