[2025-05-10T03:28:41.931+0000] {local_task_job_runner.py:120} INFO - ::group::Pre task execution logs
[2025-05-10T03:28:41.988+0000] {taskinstance.py:2073} INFO - Dependencies all met for dep_context=non-requeueable deps ti=<TaskInstance: get_price_btc_price_by_day.get_data manual__2025-05-10T03:28:38.622295+00:00 [queued]>
[2025-05-10T03:28:42.004+0000] {taskinstance.py:2073} INFO - Dependencies all met for dep_context=requeueable deps ti=<TaskInstance: get_price_btc_price_by_day.get_data manual__2025-05-10T03:28:38.622295+00:00 [queued]>
[2025-05-10T03:28:42.005+0000] {taskinstance.py:2303} INFO - Starting attempt 1 of 1
[2025-05-10T03:28:42.037+0000] {taskinstance.py:2327} INFO - Executing <Task(_PythonDecoratedOperator): get_data> on 2025-05-10 03:28:38.622295+00:00
[2025-05-10T03:28:42.047+0000] {warnings.py:110} WARNING - /home/airflow/.local/lib/python3.12/site-packages/airflow/task/task_runner/standard_task_runner.py:61: DeprecationWarning: This process (pid=48) is multi-threaded, use of fork() may lead to deadlocks in the child.
  pid = os.fork()

[2025-05-10T03:28:42.049+0000] {standard_task_runner.py:63} INFO - Started process 50 to run task
[2025-05-10T03:28:42.050+0000] {standard_task_runner.py:90} INFO - Running: ['airflow', 'tasks', 'run', 'get_price_btc_price_by_day', 'get_data', 'manual__2025-05-10T03:28:38.622295+00:00', '--job-id', '8', '--raw', '--subdir', 'DAGS_FOLDER/get_price_btc_price_by_day.py', '--cfg-path', '/tmp/tmpofqjmks7']
[2025-05-10T03:28:42.054+0000] {standard_task_runner.py:91} INFO - Job 8: Subtask get_data
[2025-05-10T03:28:42.170+0000] {task_command.py:426} INFO - Running <TaskInstance: get_price_btc_price_by_day.get_data manual__2025-05-10T03:28:38.622295+00:00 [running]> on host 840719eb5226
[2025-05-10T03:28:42.369+0000] {taskinstance.py:2644} INFO - Exporting env vars: AIRFLOW_CTX_DAG_OWNER='airflow' AIRFLOW_CTX_DAG_ID='get_price_btc_price_by_day' AIRFLOW_CTX_TASK_ID='get_data' AIRFLOW_CTX_EXECUTION_DATE='2025-05-10T03:28:38.622295+00:00' AIRFLOW_CTX_TRY_NUMBER='1' AIRFLOW_CTX_DAG_RUN_ID='manual__2025-05-10T03:28:38.622295+00:00'
[2025-05-10T03:28:42.371+0000] {taskinstance.py:430} INFO - ::endgroup::
[2025-05-10T03:28:42.373+0000] {logging_mixin.py:188} INFO - Данные за период с 2025-05-08 21:00:00+00:00 по 2025-05-09 21:00:00+00:00
[2025-05-10T03:28:42.802+0000] {taskinstance.py:441} INFO - ::group::Post task execution logs
[2025-05-10T03:28:42.803+0000] {taskinstance.py:2890} ERROR - Task failed with exception
Traceback (most recent call last):
  File "/home/airflow/.local/lib/python3.12/site-packages/airflow/models/taskinstance.py", line 465, in _execute_task
    result = _execute_callable(context=context, **execute_callable_kwargs)
             ^^^^^^^^^^^^^^^^^^^^^^^^^^^^^^^^^^^^^^^^^^^^^^^^^^^^^^^^^^^^^
  File "/home/airflow/.local/lib/python3.12/site-packages/airflow/models/taskinstance.py", line 432, in _execute_callable
    return execute_callable(context=context, **execute_callable_kwargs)
           ^^^^^^^^^^^^^^^^^^^^^^^^^^^^^^^^^^^^^^^^^^^^^^^^^^^^^^^^^^^^
  File "/home/airflow/.local/lib/python3.12/site-packages/airflow/models/baseoperator.py", line 400, in wrapper
    return func(self, *args, **kwargs)
           ^^^^^^^^^^^^^^^^^^^^^^^^^^^
  File "/home/airflow/.local/lib/python3.12/site-packages/airflow/decorators/base.py", line 265, in execute
    return_value = super().execute(context)
                   ^^^^^^^^^^^^^^^^^^^^^^^^
  File "/home/airflow/.local/lib/python3.12/site-packages/airflow/models/baseoperator.py", line 400, in wrapper
    return func(self, *args, **kwargs)
           ^^^^^^^^^^^^^^^^^^^^^^^^^^^
  File "/home/airflow/.local/lib/python3.12/site-packages/airflow/operators/python.py", line 235, in execute
    return_value = self.execute_callable()
                   ^^^^^^^^^^^^^^^^^^^^^^^
  File "/home/airflow/.local/lib/python3.12/site-packages/airflow/operators/python.py", line 252, in execute_callable
    return self.python_callable(*self.op_args, **self.op_kwargs)
           ^^^^^^^^^^^^^^^^^^^^^^^^^^^^^^^^^^^^^^^^^^^^^^^^^^^^^
  File "/opt/airflow/dags/get_price_btc_price_by_day.py", line 34, in get_data
    response.raise_for_status()
  File "/home/airflow/.local/lib/python3.12/site-packages/requests/models.py", line 1021, in raise_for_status
    raise HTTPError(http_error_msg, response=self)
requests.exceptions.HTTPError: 404 Client Error: Not Found for url: https://api.bybit.com/v2/public/tickers?symbol=BTCUSD
[2025-05-10T03:28:42.834+0000] {taskinstance.py:1205} INFO - Marking task as FAILED. dag_id=get_price_btc_price_by_day, task_id=get_data, execution_date=20250510T032838, start_date=20250510T032841, end_date=20250510T032842
[2025-05-10T03:28:42.858+0000] {standard_task_runner.py:110} ERROR - Failed to execute job 8 for task get_data (404 Client Error: Not Found for url: https://api.bybit.com/v2/public/tickers?symbol=BTCUSD; 50)
[2025-05-10T03:28:42.873+0000] {local_task_job_runner.py:240} INFO - Task exited with return code 1
[2025-05-10T03:28:42.924+0000] {taskinstance.py:3482} INFO - 0 downstream tasks scheduled from follow-on schedule check
[2025-05-10T03:28:42.930+0000] {local_task_job_runner.py:222} INFO - ::endgroup::
