[2025-05-10T03:34:13.366+0000] {task_context_logger.py:104} ERROR - Executor reports task instance <TaskInstance: get_price_btc_price_by_day.get_data manual__2025-05-10T03:28:38.622295+00:00 [queued]> finished (failed) although the task says it's queued. (Info: None) Was the task killed externally?
