[2025-05-11T10:44:12.701+0000] {local_task_job_runner.py:120} INFO - ::group::Pre task execution logs
[2025-05-11T10:44:12.788+0000] {taskinstance.py:2073} INFO - Dependencies all met for dep_context=non-requeueable deps ti=<TaskInstance: get_price_btc_price_by_day.save_to_db manual__2025-05-10T03:58:30.852756+00:00 [queued]>
[2025-05-11T10:44:12.818+0000] {taskinstance.py:2073} INFO - Dependencies all met for dep_context=requeueable deps ti=<TaskInstance: get_price_btc_price_by_day.save_to_db manual__2025-05-10T03:58:30.852756+00:00 [queued]>
[2025-05-11T10:44:12.819+0000] {taskinstance.py:2303} INFO - Starting attempt 3 of 3
[2025-05-11T10:44:12.881+0000] {taskinstance.py:2327} INFO - Executing <Task(_PythonDecoratedOperator): save_to_db> on 2025-05-10 03:58:30.852756+00:00
[2025-05-11T10:44:12.890+0000] {warnings.py:110} WARNING - /home/airflow/.local/lib/python3.12/site-packages/airflow/task/task_runner/standard_task_runner.py:61: DeprecationWarning: This process (pid=187) is multi-threaded, use of fork() may lead to deadlocks in the child.
  pid = os.fork()

[2025-05-11T10:44:12.894+0000] {standard_task_runner.py:63} INFO - Started process 191 to run task
[2025-05-11T10:44:12.900+0000] {standard_task_runner.py:90} INFO - Running: ['airflow', 'tasks', 'run', 'get_price_btc_price_by_day', 'save_to_db', 'manual__2025-05-10T03:58:30.852756+00:00', '--job-id', '75', '--raw', '--subdir', 'DAGS_FOLDER/get_price_btc_price_by_day.py', '--cfg-path', '/tmp/tmp_whskqrk']
[2025-05-11T10:44:12.907+0000] {standard_task_runner.py:91} INFO - Job 75: Subtask save_to_db
[2025-05-11T10:44:13.069+0000] {task_command.py:426} INFO - Running <TaskInstance: get_price_btc_price_by_day.save_to_db manual__2025-05-10T03:58:30.852756+00:00 [running]> on host 840719eb5226
[2025-05-11T10:44:13.385+0000] {taskinstance.py:2644} INFO - Exporting env vars: AIRFLOW_CTX_DAG_OWNER='airflow' AIRFLOW_CTX_DAG_ID='get_price_btc_price_by_day' AIRFLOW_CTX_TASK_ID='save_to_db' AIRFLOW_CTX_EXECUTION_DATE='2025-05-10T03:58:30.852756+00:00' AIRFLOW_CTX_TRY_NUMBER='3' AIRFLOW_CTX_DAG_RUN_ID='manual__2025-05-10T03:58:30.852756+00:00'
[2025-05-11T10:44:13.386+0000] {taskinstance.py:430} INFO - ::endgroup::
[2025-05-11T10:44:13.428+0000] {base.py:84} INFO - Using connection ID 'etl_db' for task execution.
[2025-05-11T10:44:13.601+0000] {taskinstance.py:441} INFO - ::group::Post task execution logs
[2025-05-11T10:44:13.601+0000] {taskinstance.py:2890} ERROR - Task failed with exception
Traceback (most recent call last):
  File "/home/airflow/.local/lib/python3.12/site-packages/sqlalchemy/engine/base.py", line 1910, in _execute_context
    self.dialect.do_execute(
  File "/home/airflow/.local/lib/python3.12/site-packages/sqlalchemy/engine/default.py", line 736, in do_execute
    cursor.execute(statement, parameters)
psycopg2.errors.InvalidDatetimeFormat: invalid input syntax for type timestamp: "data_interval_start"
LINE 1: ...24h, bid_price, ask_price, open_interest) VALUES ('data_inte...
                                                             ^


The above exception was the direct cause of the following exception:

Traceback (most recent call last):
  File "/home/airflow/.local/lib/python3.12/site-packages/airflow/models/taskinstance.py", line 465, in _execute_task
    result = _execute_callable(context=context, **execute_callable_kwargs)
             ^^^^^^^^^^^^^^^^^^^^^^^^^^^^^^^^^^^^^^^^^^^^^^^^^^^^^^^^^^^^^
  File "/home/airflow/.local/lib/python3.12/site-packages/airflow/models/taskinstance.py", line 432, in _execute_callable
    return execute_callable(context=context, **execute_callable_kwargs)
           ^^^^^^^^^^^^^^^^^^^^^^^^^^^^^^^^^^^^^^^^^^^^^^^^^^^^^^^^^^^^
  File "/home/airflow/.local/lib/python3.12/site-packages/airflow/models/baseoperator.py", line 400, in wrapper
    return func(self, *args, **kwargs)
           ^^^^^^^^^^^^^^^^^^^^^^^^^^^
  File "/home/airflow/.local/lib/python3.12/site-packages/airflow/decorators/base.py", line 265, in execute
    return_value = super().execute(context)
                   ^^^^^^^^^^^^^^^^^^^^^^^^
  File "/home/airflow/.local/lib/python3.12/site-packages/airflow/models/baseoperator.py", line 400, in wrapper
    return func(self, *args, **kwargs)
           ^^^^^^^^^^^^^^^^^^^^^^^^^^^
  File "/home/airflow/.local/lib/python3.12/site-packages/airflow/operators/python.py", line 235, in execute
    return_value = self.execute_callable()
                   ^^^^^^^^^^^^^^^^^^^^^^^
  File "/home/airflow/.local/lib/python3.12/site-packages/airflow/operators/python.py", line 252, in execute_callable
    return self.python_callable(*self.op_args, **self.op_kwargs)
           ^^^^^^^^^^^^^^^^^^^^^^^^^^^^^^^^^^^^^^^^^^^^^^^^^^^^^
  File "/opt/airflow/dags/get_price_btc_price_by_day.py", line 97, in save_to_db
    connection.execute(stmt)
  File "/home/airflow/.local/lib/python3.12/site-packages/sqlalchemy/engine/base.py", line 1385, in execute
    return meth(self, multiparams, params, _EMPTY_EXECUTION_OPTS)
           ^^^^^^^^^^^^^^^^^^^^^^^^^^^^^^^^^^^^^^^^^^^^^^^^^^^^^^
  File "/home/airflow/.local/lib/python3.12/site-packages/sqlalchemy/sql/elements.py", line 334, in _execute_on_connection
    return connection._execute_clauseelement(
           ^^^^^^^^^^^^^^^^^^^^^^^^^^^^^^^^^^
  File "/home/airflow/.local/lib/python3.12/site-packages/sqlalchemy/engine/base.py", line 1577, in _execute_clauseelement
    ret = self._execute_context(
          ^^^^^^^^^^^^^^^^^^^^^^
  File "/home/airflow/.local/lib/python3.12/site-packages/sqlalchemy/engine/base.py", line 1953, in _execute_context
    self._handle_dbapi_exception(
  File "/home/airflow/.local/lib/python3.12/site-packages/sqlalchemy/engine/base.py", line 2134, in _handle_dbapi_exception
    util.raise_(
  File "/home/airflow/.local/lib/python3.12/site-packages/sqlalchemy/util/compat.py", line 211, in raise_
    raise exception
  File "/home/airflow/.local/lib/python3.12/site-packages/sqlalchemy/engine/base.py", line 1910, in _execute_context
    self.dialect.do_execute(
  File "/home/airflow/.local/lib/python3.12/site-packages/sqlalchemy/engine/default.py", line 736, in do_execute
    cursor.execute(statement, parameters)
sqlalchemy.exc.DataError: (psycopg2.errors.InvalidDatetimeFormat) invalid input syntax for type timestamp: "data_interval_start"
LINE 1: ...24h, bid_price, ask_price, open_interest) VALUES ('data_inte...
                                                             ^

[SQL: INSERT INTO etl.get_price_btc_price_by_day (data_interval_start, data_interval_end, last_price, volume_24h, high_price_24h, low_price_24h, bid_price, ask_price, open_interest) VALUES (%(data_interval_start)s, %(data_interval_end)s, %(last_price)s, %(volume_24h)s, %(high_price_24h)s, %(low_price_24h)s, %(bid_price)s, %(ask_price)s, %(open_interest)s) ON CONFLICT (data_interval_start) DO NOTHING]
[parameters: {'data_interval_start': 'data_interval_start', 'data_interval_end': 'data_interval_end', 'last_price': 'last_price', 'volume_24h': 'volume_24h', 'high_price_24h': 'high_price_24h', 'low_price_24h': 'low_price_24h', 'bid_price': 'bid_price', 'ask_price': 'ask_price', 'open_interest': 'open_interest'}]
(Background on this error at: https://sqlalche.me/e/14/9h9h)
[2025-05-11T10:44:13.656+0000] {taskinstance.py:1205} INFO - Marking task as FAILED. dag_id=get_price_btc_price_by_day, task_id=save_to_db, execution_date=20250510T035830, start_date=20250511T104412, end_date=20250511T104413
[2025-05-11T10:44:13.724+0000] {standard_task_runner.py:110} ERROR - Failed to execute job 75 for task save_to_db ((psycopg2.errors.InvalidDatetimeFormat) invalid input syntax for type timestamp: "data_interval_start"
LINE 1: ...24h, bid_price, ask_price, open_interest) VALUES ('data_inte...
                                                             ^

[SQL: INSERT INTO etl.get_price_btc_price_by_day (data_interval_start, data_interval_end, last_price, volume_24h, high_price_24h, low_price_24h, bid_price, ask_price, open_interest) VALUES (%(data_interval_start)s, %(data_interval_end)s, %(last_price)s, %(volume_24h)s, %(high_price_24h)s, %(low_price_24h)s, %(bid_price)s, %(ask_price)s, %(open_interest)s) ON CONFLICT (data_interval_start) DO NOTHING]
[parameters: {'data_interval_start': 'data_interval_start', 'data_interval_end': 'data_interval_end', 'last_price': 'last_price', 'volume_24h': 'volume_24h', 'high_price_24h': 'high_price_24h', 'low_price_24h': 'low_price_24h', 'bid_price': 'bid_price', 'ask_price': 'ask_price', 'open_interest': 'open_interest'}]
(Background on this error at: https://sqlalche.me/e/14/9h9h); 191)
[2025-05-11T10:44:13.750+0000] {local_task_job_runner.py:240} INFO - Task exited with return code 1
[2025-05-11T10:44:13.814+0000] {taskinstance.py:3482} INFO - 1 downstream tasks scheduled from follow-on schedule check
[2025-05-11T10:44:13.820+0000] {local_task_job_runner.py:222} INFO - ::endgroup::
